/home/amaya.dharmasiri/.conda/envs/VL-LTR/lib/python3.10/site-packages/torch/distributed/launch.py:178: FutureWarning: The module torch.distributed.launch is deprecated
and will be removed in future. Use torchrun.
Note that --use_env is set by default in torchrun.
If your script expects `--local_rank` argument to be set, please
change it to read from `os.environ['LOCAL_RANK']` instead. See 
https://pytorch.org/docs/stable/distributed.html#launch-utility for 
further instructions

  warnings.warn(
WARNING:torch.distributed.run:
*****************************************
Setting OMP_NUM_THREADS environment variable for each process to be 1 in default, to avoid your system being overloaded, please further tune the variable for optimal performance in your application as needed. 
*****************************************
| distributed init (rank 1, word 8): env://
| distributed init (rank 3, word 8): env://
Traceback (most recent call last):
  File "/home/amaya.dharmasiri/LongTail/VL-LTR/main.py", line 528, in <module>
    main(args)
  File "/home/amaya.dharmasiri/LongTail/VL-LTR/main.py", line 234, in main
    utils.init_distributed_mode(args)
  File "/home/amaya.dharmasiri/LongTail/VL-LTR/utils.py", line 227, in init_distributed_mode
    torch.cuda.set_device(args.gpu)
  File "/home/amaya.dharmasiri/.conda/envs/VL-LTR/lib/python3.10/site-packages/torch/cuda/__init__.py", line 314, in set_device
    torch._C._cuda_setDevice(device)
RuntimeError: CUDA error: invalid device ordinal
CUDA kernel errors might be asynchronously reported at some other API call,so the stacktrace below might be incorrect.
For debugging consider passing CUDA_LAUNCH_BLOCKING=1.
Traceback (most recent call last):
  File "/home/amaya.dharmasiri/LongTail/VL-LTR/main.py", line 528, in <module>
    main(args)
  File "/home/amaya.dharmasiri/LongTail/VL-LTR/main.py", line 234, in main
    utils.init_distributed_mode(args)
  File "/home/amaya.dharmasiri/LongTail/VL-LTR/utils.py", line 227, in init_distributed_mode
    torch.cuda.set_device(args.gpu)
  File "/home/amaya.dharmasiri/.conda/envs/VL-LTR/lib/python3.10/site-packages/torch/cuda/__init__.py", line 314, in set_device
    torch._C._cuda_setDevice(device)
RuntimeError: CUDA error: invalid device ordinal
CUDA kernel errors might be asynchronously reported at some other API call,so the stacktrace below might be incorrect.
For debugging consider passing CUDA_LAUNCH_BLOCKING=1.
Traceback (most recent call last):
  File "/home/amaya.dharmasiri/LongTail/VL-LTR/main.py", line 528, in <module>
    main(args)
  File "/home/amaya.dharmasiri/LongTail/VL-LTR/main.py", line 234, in main
    utils.init_distributed_mode(args)
  File "/home/amaya.dharmasiri/LongTail/VL-LTR/utils.py", line 227, in init_distributed_mode
    torch.cuda.set_device(args.gpu)
  File "/home/amaya.dharmasiri/.conda/envs/VL-LTR/lib/python3.10/site-packages/torch/cuda/__init__.py", line 314, in set_device
    torch._C._cuda_setDevice(device)
RuntimeError: CUDA error: invalid device ordinal
CUDA kernel errors might be asynchronously reported at some other API call,so the stacktrace below might be incorrect.
For debugging consider passing CUDA_LAUNCH_BLOCKING=1.
Traceback (most recent call last):
  File "/home/amaya.dharmasiri/LongTail/VL-LTR/main.py", line 528, in <module>
    main(args)
  File "/home/amaya.dharmasiri/LongTail/VL-LTR/main.py", line 234, in main
    utils.init_distributed_mode(args)
  File "/home/amaya.dharmasiri/LongTail/VL-LTR/utils.py", line 227, in init_distributed_mode
    torch.cuda.set_device(args.gpu)
  File "/home/amaya.dharmasiri/.conda/envs/VL-LTR/lib/python3.10/site-packages/torch/cuda/__init__.py", line 314, in set_device
    torch._C._cuda_setDevice(device)
RuntimeError: CUDA error: invalid device ordinal
CUDA kernel errors might be asynchronously reported at some other API call,so the stacktrace below might be incorrect.
For debugging consider passing CUDA_LAUNCH_BLOCKING=1.
| distributed init (rank 2, word 8): env://
| distributed init (rank 0, word 8): env://
WARNING:torch.distributed.elastic.multiprocessing.api:Sending process 1157360 closing signal SIGTERM
WARNING:torch.distributed.elastic.multiprocessing.api:Sending process 1157361 closing signal SIGTERM
WARNING:torch.distributed.elastic.multiprocessing.api:Sending process 1157362 closing signal SIGTERM
WARNING:torch.distributed.elastic.multiprocessing.api:Sending process 1157363 closing signal SIGTERM
ERROR:torch.distributed.elastic.multiprocessing.api:failed (exitcode: 1) local_rank: 4 (pid: 1157364) of binary: /home/amaya.dharmasiri/.conda/envs/VL-LTR/bin/python
Traceback (most recent call last):
  File "/home/amaya.dharmasiri/.conda/envs/VL-LTR/lib/python3.10/runpy.py", line 196, in _run_module_as_main
    return _run_code(code, main_globals, None,
  File "/home/amaya.dharmasiri/.conda/envs/VL-LTR/lib/python3.10/runpy.py", line 86, in _run_code
    exec(code, run_globals)
  File "/home/amaya.dharmasiri/.conda/envs/VL-LTR/lib/python3.10/site-packages/torch/distributed/launch.py", line 193, in <module>
    main()
  File "/home/amaya.dharmasiri/.conda/envs/VL-LTR/lib/python3.10/site-packages/torch/distributed/launch.py", line 189, in main
    launch(args)
  File "/home/amaya.dharmasiri/.conda/envs/VL-LTR/lib/python3.10/site-packages/torch/distributed/launch.py", line 174, in launch
    run(args)
  File "/home/amaya.dharmasiri/.conda/envs/VL-LTR/lib/python3.10/site-packages/torch/distributed/run.py", line 752, in run
    elastic_launch(
  File "/home/amaya.dharmasiri/.conda/envs/VL-LTR/lib/python3.10/site-packages/torch/distributed/launcher/api.py", line 131, in __call__
    return launch_agent(self._config, self._entrypoint, list(args))
  File "/home/amaya.dharmasiri/.conda/envs/VL-LTR/lib/python3.10/site-packages/torch/distributed/launcher/api.py", line 245, in launch_agent
    raise ChildFailedError(
torch.distributed.elastic.multiprocessing.errors.ChildFailedError: 
============================================================
main.py FAILED
------------------------------------------------------------
Failures:
[1]:
  time      : 2022-08-05_11:01:18
  host      : gpu-03
  rank      : 5 (local_rank: 5)
  exitcode  : 1 (pid: 1157365)
  error_file: <N/A>
  traceback : To enable traceback see: https://pytorch.org/docs/stable/elastic/errors.html
[2]:
  time      : 2022-08-05_11:01:18
  host      : gpu-03
  rank      : 6 (local_rank: 6)
  exitcode  : 1 (pid: 1157366)
  error_file: <N/A>
  traceback : To enable traceback see: https://pytorch.org/docs/stable/elastic/errors.html
[3]:
  time      : 2022-08-05_11:01:18
  host      : gpu-03
  rank      : 7 (local_rank: 7)
  exitcode  : 1 (pid: 1157367)
  error_file: <N/A>
  traceback : To enable traceback see: https://pytorch.org/docs/stable/elastic/errors.html
------------------------------------------------------------
Root Cause (first observed failure):
[0]:
  time      : 2022-08-05_11:01:18
  host      : gpu-03
  rank      : 4 (local_rank: 4)
  exitcode  : 1 (pid: 1157364)
  error_file: <N/A>
  traceback : To enable traceback see: https://pytorch.org/docs/stable/elastic/errors.html
============================================================
